 flask db upgrade
INFO  [alembic.runtime.migration] Context impl PostgresqlImpl.
INFO  [alembic.runtime.migration] Will assume transactional DDL.
INFO  [alembic.runtime.migration] Running upgrade  -> ba148351d994, Add force_password_change field to User model
Traceback (most recent call last):
  File "/home/test/.local/lib/python3.10/site-packages/sqlalchemy/engine/base.py", line 1964, in _exec_single_context
    self.dialect.do_execute(
  File "/home/test/.local/lib/python3.10/site-packages/sqlalchemy/engine/default.py", line 945, in do_execute
    cursor.execute(statement, parameters)
psycopg2.errors.DuplicateColumn: column "force_password_change" of relation "user" already exists


The above exception was the direct cause of the following exception:

Traceback (most recent call last):
  File "/home/test/.local/bin/flask", line 8, in <module>
    sys.exit(main())
  File "/home/test/.local/lib/python3.10/site-packages/flask/cli.py", line 1129, in main
    cli.main()
  File "/home/test/.local/lib/python3.10/site-packages/click/core.py", line 1082, in main
    rv = self.invoke(ctx)
  File "/home/test/.local/lib/python3.10/site-packages/click/core.py", line 1697, in invoke
    return _process_result(sub_ctx.command.invoke(sub_ctx))
  File "/home/test/.local/lib/python3.10/site-packages/click/core.py", line 1697, in invoke
    return _process_result(sub_ctx.command.invoke(sub_ctx))
  File "/home/test/.local/lib/python3.10/site-packages/click/core.py", line 1443, in invoke
    return ctx.invoke(self.callback, **ctx.params)
  File "/home/test/.local/lib/python3.10/site-packages/click/core.py", line 788, in invoke
    return __callback(*args, **kwargs)
  File "/home/test/.local/lib/python3.10/site-packages/click/decorators.py", line 33, in new_func
    return f(get_current_context(), *args, **kwargs)
  File "/home/test/.local/lib/python3.10/site-packages/flask/cli.py", line 400, in decorator
    return ctx.invoke(f, *args, **kwargs)
  File "/home/test/.local/lib/python3.10/site-packages/click/core.py", line 788, in invoke
    return __callback(*args, **kwargs)
  File "/home/test/.local/lib/python3.10/site-packages/flask_migrate/cli.py", line 157, in upgrade
    _upgrade(directory or g.directory, revision, sql, tag, x_arg or g.x_arg)
  File "/home/test/.local/lib/python3.10/site-packages/flask_migrate/__init__.py", line 111, in wrapped
    f(*args, **kwargs)
  File "/home/test/.local/lib/python3.10/site-packages/flask_migrate/__init__.py", line 200, in upgrade
    command.upgrade(config, revision, sql=sql, tag=tag)
  File "/home/test/.local/lib/python3.10/site-packages/alembic/command.py", line 408, in upgrade
    script.run_env()
  File "/home/test/.local/lib/python3.10/site-packages/alembic/script/base.py", line 586, in run_env
    util.load_python_file(self.dir, "env.py")
  File "/home/test/.local/lib/python3.10/site-packages/alembic/util/pyfiles.py", line 95, in load_python_file
    module = load_module_py(module_id, path)
  File "/home/test/.local/lib/python3.10/site-packages/alembic/util/pyfiles.py", line 113, in load_module_py
    spec.loader.exec_module(module)  # type: ignore
  File "<frozen importlib._bootstrap_external>", line 883, in exec_module
  File "<frozen importlib._bootstrap>", line 241, in _call_with_frames_removed
  File "/home/test/project/emp_hr/SmartTaskTracker/migrations/env.py", line 113, in <module>
    run_migrations_online()
  File "/home/test/project/emp_hr/SmartTaskTracker/migrations/env.py", line 107, in run_migrations_online
    context.run_migrations()
  File "<string>", line 8, in run_migrations
  File "/home/test/.local/lib/python3.10/site-packages/alembic/runtime/environment.py", line 946, in run_migrations
    self.get_context().run_migrations(**kw)
  File "/home/test/.local/lib/python3.10/site-packages/alembic/runtime/migration.py", line 623, in run_migrations
    step.migration_fn(**kw)
  File "/home/test/project/emp_hr/SmartTaskTracker/migrations/versions/ba148351d994_add_force_password_change_field_to_user_.py", line 21, in upgrade
    with op.batch_alter_table('user', schema=None) as batch_op:
  File "/usr/lib/python3.10/contextlib.py", line 142, in __exit__
    next(self.gen)
  File "/home/test/.local/lib/python3.10/site-packages/alembic/operations/base.py", line 397, in batch_alter_table
    impl.flush()
  File "/home/test/.local/lib/python3.10/site-packages/alembic/operations/batch.py", line 115, in flush
    fn(*arg, **kw)
  File "/home/test/.local/lib/python3.10/site-packages/alembic/ddl/impl.py", line 373, in add_column
    self._exec(base.AddColumn(table_name, column, schema=schema))
  File "/home/test/.local/lib/python3.10/site-packages/alembic/ddl/impl.py", line 246, in _exec
    return conn.execute(construct, params)
  File "/home/test/.local/lib/python3.10/site-packages/sqlalchemy/engine/base.py", line 1416, in execute
    return meth(
  File "/home/test/.local/lib/python3.10/site-packages/sqlalchemy/sql/ddl.py", line 187, in _execute_on_connection
    return connection._execute_ddl(
  File "/home/test/.local/lib/python3.10/site-packages/sqlalchemy/engine/base.py", line 1527, in _execute_ddl
    ret = self._execute_context(
  File "/home/test/.local/lib/python3.10/site-packages/sqlalchemy/engine/base.py", line 1843, in _execute_context
    return self._exec_single_context(
  File "/home/test/.local/lib/python3.10/site-packages/sqlalchemy/engine/base.py", line 1983, in _exec_single_context
    self._handle_dbapi_exception(
  File "/home/test/.local/lib/python3.10/site-packages/sqlalchemy/engine/base.py", line 2352, in _handle_dbapi_exception
    raise sqlalchemy_exception.with_traceback(exc_info[2]) from e
  File "/home/test/.local/lib/python3.10/site-packages/sqlalchemy/engine/base.py", line 1964, in _exec_single_context
    self.dialect.do_execute(
  File "/home/test/.local/lib/python3.10/site-packages/sqlalchemy/engine/default.py", line 945, in do_execute
    cursor.execute(statement, parameters)
sqlalchemy.exc.ProgrammingError: (psycopg2.errors.DuplicateColumn) column "force_password_change" of relation "user" already exists

[SQL: ALTER TABLE "user" ADD COLUMN force_password_change BOOLEAN]
(Background on this error at: https://sqlalche.me/e/20/f405)